Traceback (most recent call last):
  File "C:\Users\UPWr\AppData\Roaming\Python\Python311\site-packages\jupyter_cache\executors\utils.py", line 58, in single_nb_execution
    executenb(
  File "C:\ProgramData\anaconda3\Lib\site-packages\nbclient\client.py", line 1204, in execute
    return NotebookClient(nb=nb, resources=resources, km=km, **kwargs).execute()
           ^^^^^^^^^^^^^^^^^^^^^^^^^^^^^^^^^^^^^^^^^^^^^^^^^^^^^^^^^^^^^^^^^^^^^
  File "C:\ProgramData\anaconda3\Lib\site-packages\nbclient\util.py", line 84, in wrapped
    return just_run(coro(*args, **kwargs))
           ^^^^^^^^^^^^^^^^^^^^^^^^^^^^^^^
  File "C:\ProgramData\anaconda3\Lib\site-packages\nbclient\util.py", line 62, in just_run
    return loop.run_until_complete(coro)
           ^^^^^^^^^^^^^^^^^^^^^^^^^^^^^
  File "C:\ProgramData\anaconda3\Lib\asyncio\base_events.py", line 653, in run_until_complete
    return future.result()
           ^^^^^^^^^^^^^^^
  File "C:\ProgramData\anaconda3\Lib\site-packages\nbclient\client.py", line 663, in async_execute
    await self.async_execute_cell(
  File "C:\ProgramData\anaconda3\Lib\site-packages\nbclient\client.py", line 965, in async_execute_cell
    await self._check_raise_for_error(cell, cell_index, exec_reply)
  File "C:\ProgramData\anaconda3\Lib\site-packages\nbclient\client.py", line 862, in _check_raise_for_error
    raise CellExecutionError.from_cell_and_msg(cell, exec_reply_content)
nbclient.exceptions.CellExecutionError: An error occurred while executing the following cell:
------------------
Image(url='https://upload.wikimedia.org/wikipedia/commons/a/a9/Rube_Goldberg%27s_%22Self-Operating_Napkin%22_%28cropped%29.gif')
------------------

[1;31m---------------------------------------------------------------------------[0m
[1;31mNameError[0m                                 Traceback (most recent call last)
Cell [1;32mIn[4], line 1[0m
[1;32m----> 1[0m Image(url[38;5;241m=[39m[38;5;124m'[39m[38;5;124mhttps://upload.wikimedia.org/wikipedia/commons/a/a9/Rube_Goldberg[39m[38;5;132;01m%27s[39;00m[38;5;124m_[39m[38;5;124m%[39m[38;5;124m22Self-Operating_Napkin[39m[38;5;124m%[39m[38;5;124m22_[39m[38;5;132;01m%28c[39;00m[38;5;124mropped[39m[38;5;124m%[39m[38;5;124m29.gif[39m[38;5;124m'[39m)

[1;31mNameError[0m: name 'Image' is not defined
NameError: name 'Image' is not defined

