Traceback (most recent call last):
  File "C:\Users\UPWr\AppData\Roaming\Python\Python311\site-packages\jupyter_cache\executors\utils.py", line 58, in single_nb_execution
    executenb(
  File "C:\ProgramData\anaconda3\Lib\site-packages\nbclient\client.py", line 1204, in execute
    return NotebookClient(nb=nb, resources=resources, km=km, **kwargs).execute()
           ^^^^^^^^^^^^^^^^^^^^^^^^^^^^^^^^^^^^^^^^^^^^^^^^^^^^^^^^^^^^^^^^^^^^^
  File "C:\ProgramData\anaconda3\Lib\site-packages\nbclient\util.py", line 84, in wrapped
    return just_run(coro(*args, **kwargs))
           ^^^^^^^^^^^^^^^^^^^^^^^^^^^^^^^
  File "C:\ProgramData\anaconda3\Lib\site-packages\nbclient\util.py", line 62, in just_run
    return loop.run_until_complete(coro)
           ^^^^^^^^^^^^^^^^^^^^^^^^^^^^^
  File "C:\ProgramData\anaconda3\Lib\asyncio\base_events.py", line 653, in run_until_complete
    return future.result()
           ^^^^^^^^^^^^^^^
  File "C:\ProgramData\anaconda3\Lib\site-packages\nbclient\client.py", line 663, in async_execute
    await self.async_execute_cell(
  File "C:\ProgramData\anaconda3\Lib\site-packages\nbclient\client.py", line 965, in async_execute_cell
    await self._check_raise_for_error(cell, cell_index, exec_reply)
  File "C:\ProgramData\anaconda3\Lib\site-packages\nbclient\client.py", line 862, in _check_raise_for_error
    raise CellExecutionError.from_cell_and_msg(cell, exec_reply_content)
nbclient.exceptions.CellExecutionError: An error occurred while executing the following cell:
------------------
%run ./tmp/argparse_divide.py --dividend 42 --divisor "two"
------------------

[1;31m---------------------------------------------------------------------------[0m
[1;31mValueError[0m                                Traceback (most recent call last)
[1;32mC:\ProgramData\anaconda3\Lib\argparse.py[0m in [0;36m_get_value[1;34m(self, action, arg_string)[0m
[0;32m   2528[0m         [1;32mtry[0m[1;33m:[0m[1;33m[0m[1;33m[0m[0m
[1;32m-> 2529[1;33m             [0mresult[0m [1;33m=[0m [0mtype_func[0m[1;33m([0m[0marg_string[0m[1;33m)[0m[1;33m[0m[1;33m[0m[0m
[0m[0;32m   2530[0m [1;33m[0m[0m

[1;31mValueError[0m: invalid literal for int() with base 10: 'two'

During handling of the above exception, another exception occurred:

[1;31mArgumentError[0m                             Traceback (most recent call last)
[1;32mC:\ProgramData\anaconda3\Lib\argparse.py[0m in [0;36mparse_known_args[1;34m(self, args, namespace)[0m
[0;32m   1901[0m             [1;32mtry[0m[1;33m:[0m[1;33m[0m[1;33m[0m[0m
[1;32m-> 1902[1;33m                 [0mnamespace[0m[1;33m,[0m [0margs[0m [1;33m=[0m [0mself[0m[1;33m.[0m[0m_parse_known_args[0m[1;33m([0m[0margs[0m[1;33m,[0m [0mnamespace[0m[1;33m)[0m[1;33m[0m[1;33m[0m[0m
[0m[0;32m   1903[0m             [1;32mexcept[0m [0mArgumentError[0m [1;32mas[0m [0merr[0m[1;33m:[0m[1;33m[0m[1;33m[0m[0m

[1;32mC:\ProgramData\anaconda3\Lib\argparse.py[0m in [0;36m_parse_known_args[1;34m(self, arg_strings, namespace)[0m
[0;32m   2113[0m             [1;31m# consume the next optional and any arguments for it[0m[1;33m[0m[1;33m[0m[0m
[1;32m-> 2114[1;33m             [0mstart_index[0m [1;33m=[0m [0mconsume_optional[0m[1;33m([0m[0mstart_index[0m[1;33m)[0m[1;33m[0m[1;33m[0m[0m
[0m[0;32m   2115[0m [1;33m[0m[0m

[1;32mC:\ProgramData\anaconda3\Lib\argparse.py[0m in [0;36mconsume_optional[1;34m(start_index)[0m
[0;32m   2053[0m             [1;32mfor[0m [0maction[0m[1;33m,[0m [0margs[0m[1;33m,[0m [0moption_string[0m [1;32min[0m [0maction_tuples[0m[1;33m:[0m[1;33m[0m[1;33m[0m[0m
[1;32m-> 2054[1;33m                 [0mtake_action[0m[1;33m([0m[0maction[0m[1;33m,[0m [0margs[0m[1;33m,[0m [0moption_string[0m[1;33m)[0m[1;33m[0m[1;33m[0m[0m
[0m[0;32m   2055[0m             [1;32mreturn[0m [0mstop[0m[1;33m[0m[1;33m[0m[0m

[1;32mC:\ProgramData\anaconda3\Lib\argparse.py[0m in [0;36mtake_action[1;34m(action, argument_strings, option_string)[0m
[0;32m   1961[0m             [0mseen_actions[0m[1;33m.[0m[0madd[0m[1;33m([0m[0maction[0m[1;33m)[0m[1;33m[0m[1;33m[0m[0m
[1;32m-> 1962[1;33m             [0margument_values[0m [1;33m=[0m [0mself[0m[1;33m.[0m[0m_get_values[0m[1;33m([0m[0maction[0m[1;33m,[0m [0margument_strings[0m[1;33m)[0m[1;33m[0m[1;33m[0m[0m
[0m[0;32m   1963[0m [1;33m[0m[0m

[1;32mC:\ProgramData\anaconda3\Lib\argparse.py[0m in [0;36m_get_values[1;34m(self, action, arg_strings)[0m
[0;32m   2495[0m             [0marg_string[0m[1;33m,[0m [1;33m=[0m [0marg_strings[0m[1;33m[0m[1;33m[0m[0m
[1;32m-> 2496[1;33m             [0mvalue[0m [1;33m=[0m [0mself[0m[1;33m.[0m[0m_get_value[0m[1;33m([0m[0maction[0m[1;33m,[0m [0marg_string[0m[1;33m)[0m[1;33m[0m[1;33m[0m[0m
[0m[0;32m   2497[0m             [0mself[0m[1;33m.[0m[0m_check_value[0m[1;33m([0m[0maction[0m[1;33m,[0m [0mvalue[0m[1;33m)[0m[1;33m[0m[1;33m[0m[0m

[1;32mC:\ProgramData\anaconda3\Lib\argparse.py[0m in [0;36m_get_value[1;34m(self, action, arg_string)[0m
[0;32m   2541[0m             [0mmsg[0m [1;33m=[0m [0m_[0m[1;33m([0m[1;34m'invalid %(type)s value: %(value)r'[0m[1;33m)[0m[1;33m[0m[1;33m[0m[0m
[1;32m-> 2542[1;33m             [1;32mraise[0m [0mArgumentError[0m[1;33m([0m[0maction[0m[1;33m,[0m [0mmsg[0m [1;33m%[0m [0margs[0m[1;33m)[0m[1;33m[0m[1;33m[0m[0m
[0m[0;32m   2543[0m [1;33m[0m[0m

[1;31mArgumentError[0m: argument --divisor: invalid int value: 'two'

During handling of the above exception, another exception occurred:

[1;31mSystemExit[0m                                Traceback (most recent call last)
[1;32mC:\ProgramData\anaconda3\Lib\site-packages\IPython\core\interactiveshell.py[0m in [0;36msafe_execfile[1;34m(self, fname, exit_ignore, raise_exceptions, shell_futures, *where)[0m
[0;32m   2830[0m                 [0mglob[0m[1;33m,[0m [0mloc[0m [1;33m=[0m [1;33m([0m[0mwhere[0m [1;33m+[0m [1;33m([0m[1;32mNone[0m[1;33m,[0m [1;33m)[0m[1;33m)[0m[1;33m[[0m[1;33m:[0m[1;36m2[0m[1;33m][0m[1;33m[0m[1;33m[0m[0m
[1;32m-> 2831[1;33m                 py3compat.execfile(
[0m[0;32m   2832[0m                     [0mfname[0m[1;33m,[0m [0mglob[0m[1;33m,[0m [0mloc[0m[1;33m,[0m[1;33m[0m[1;33m[0m[0m

[1;32mC:\ProgramData\anaconda3\Lib\site-packages\IPython\utils\py3compat.py[0m in [0;36mexecfile[1;34m(fname, glob, loc, compiler)[0m
[0;32m    167[0m         [0mcompiler[0m [1;33m=[0m [0mcompiler[0m [1;32mor[0m [0mcompile[0m[1;33m[0m[1;33m[0m[0m
[1;32m--> 168[1;33m         [0mexec[0m[1;33m([0m[0mcompiler[0m[1;33m([0m[0mf[0m[1;33m.[0m[0mread[0m[1;33m([0m[1;33m)[0m[1;33m,[0m [0mfname[0m[1;33m,[0m [1;34m'exec'[0m[1;33m)[0m[1;33m,[0m [0mglob[0m[1;33m,[0m [0mloc[0m[1;33m)[0m[1;33m[0m[1;33m[0m[0m
[0m[0;32m    169[0m [1;33m[0m[0m

[1;32mE:\MATERIALY\IGGPyCourse\IGGPyCourse\tmp\argparse_divide.py[0m in [0;36m<module>[1;34m[0m
[0;32m      8[0m [1;33m[0m[0m
[1;32m----> 9[1;33m [0margs[0m [1;33m=[0m [0mparser[0m[1;33m.[0m[0mparse_args[0m[1;33m([0m[1;33m)[0m[1;33m[0m[1;33m[0m[0m
[0m[0;32m     10[0m [1;33m[0m[0m

[1;32mC:\ProgramData\anaconda3\Lib\argparse.py[0m in [0;36mparse_args[1;34m(self, args, namespace)[0m
[0;32m   1868[0m     [1;32mdef[0m [0mparse_args[0m[1;33m([0m[0mself[0m[1;33m,[0m [0margs[0m[1;33m=[0m[1;32mNone[0m[1;33m,[0m [0mnamespace[0m[1;33m=[0m[1;32mNone[0m[1;33m)[0m[1;33m:[0m[1;33m[0m[1;33m[0m[0m
[1;32m-> 1869[1;33m         [0margs[0m[1;33m,[0m [0margv[0m [1;33m=[0m [0mself[0m[1;33m.[0m[0mparse_known_args[0m[1;33m([0m[0margs[0m[1;33m,[0m [0mnamespace[0m[1;33m)[0m[1;33m[0m[1;33m[0m[0m
[0m[0;32m   1870[0m         [1;32mif[0m [0margv[0m[1;33m:[0m[1;33m[0m[1;33m[0m[0m

[1;32mC:\ProgramData\anaconda3\Lib\argparse.py[0m in [0;36mparse_known_args[1;34m(self, args, namespace)[0m
[0;32m   1903[0m             [1;32mexcept[0m [0mArgumentError[0m [1;32mas[0m [0merr[0m[1;33m:[0m[1;33m[0m[1;33m[0m[0m
[1;32m-> 1904[1;33m                 [0mself[0m[1;33m.[0m[0merror[0m[1;33m([0m[0mstr[0m[1;33m([0m[0merr[0m[1;33m)[0m[1;33m)[0m[1;33m[0m[1;33m[0m[0m
[0m[0;32m   1905[0m         [1;32melse[0m[1;33m:[0m[1;33m[0m[1;33m[0m[0m

[1;32mC:\ProgramData\anaconda3\Lib\argparse.py[0m in [0;36merror[1;34m(self, message)[0m
[0;32m   2627[0m         [0margs[0m [1;33m=[0m [1;33m{[0m[1;34m'prog'[0m[1;33m:[0m [0mself[0m[1;33m.[0m[0mprog[0m[1;33m,[0m [1;34m'message'[0m[1;33m:[0m [0mmessage[0m[1;33m}[0m[1;33m[0m[1;33m[0m[0m
[1;32m-> 2628[1;33m         [0mself[0m[1;33m.[0m[0mexit[0m[1;33m([0m[1;36m2[0m[1;33m,[0m [0m_[0m[1;33m([0m[1;34m'%(prog)s: error: %(message)s\n'[0m[1;33m)[0m [1;33m%[0m [0margs[0m[1;33m)[0m[1;33m[0m[1;33m[0m[0m
[0m
[1;32mC:\ProgramData\anaconda3\Lib\argparse.py[0m in [0;36mexit[1;34m(self, status, message)[0m
[0;32m   2614[0m             [0mself[0m[1;33m.[0m[0m_print_message[0m[1;33m([0m[0mmessage[0m[1;33m,[0m [0m_sys[0m[1;33m.[0m[0mstderr[0m[1;33m)[0m[1;33m[0m[1;33m[0m[0m
[1;32m-> 2615[1;33m         [0m_sys[0m[1;33m.[0m[0mexit[0m[1;33m([0m[0mstatus[0m[1;33m)[0m[1;33m[0m[1;33m[0m[0m
[0m[0;32m   2616[0m [1;33m[0m[0m

[1;31mSystemExit[0m: 2

During handling of the above exception, another exception occurred:

[1;31mTypeError[0m                                 Traceback (most recent call last)
[1;32m~\AppData\Local\Temp\ipykernel_27984\336415510.py[0m in [0;36m<cell line: 0>[1;34m()[0m
[1;32m----> 1[1;33m [0mget_ipython[0m[1;33m([0m[1;33m)[0m[1;33m.[0m[0mrun_line_magic[0m[1;33m([0m[1;34m'run'[0m[1;33m,[0m [1;34m'./tmp/argparse_divide.py --dividend 42 --divisor "two"'[0m[1;33m)[0m[1;33m[0m[1;33m[0m[0m
[0m
[1;32mC:\ProgramData\anaconda3\Lib\site-packages\IPython\core\interactiveshell.py[0m in [0;36mrun_line_magic[1;34m(self, magic_name, line, _stack_depth)[0m
[0;32m   2416[0m                 [0mkwargs[0m[1;33m[[0m[1;34m'local_ns'[0m[1;33m][0m [1;33m=[0m [0mself[0m[1;33m.[0m[0mget_local_scope[0m[1;33m([0m[0mstack_depth[0m[1;33m)[0m[1;33m[0m[1;33m[0m[0m
[0;32m   2417[0m             [1;32mwith[0m [0mself[0m[1;33m.[0m[0mbuiltin_trap[0m[1;33m:[0m[1;33m[0m[1;33m[0m[0m
[1;32m-> 2418[1;33m                 [0mresult[0m [1;33m=[0m [0mfn[0m[1;33m([0m[1;33m*[0m[0margs[0m[1;33m,[0m [1;33m**[0m[0mkwargs[0m[1;33m)[0m[1;33m[0m[1;33m[0m[0m
[0m[0;32m   2419[0m             [1;32mreturn[0m [0mresult[0m[1;33m[0m[1;33m[0m[0m
[0;32m   2420[0m [1;33m[0m[0m

[1;32mC:\ProgramData\anaconda3\Lib\site-packages\decorator.py[0m in [0;36mfun[1;34m(*args, **kw)[0m
[0;32m    230[0m             [1;32mif[0m [1;32mnot[0m [0mkwsyntax[0m[1;33m:[0m[1;33m[0m[1;33m[0m[0m
[0;32m    231[0m                 [0margs[0m[1;33m,[0m [0mkw[0m [1;33m=[0m [0mfix[0m[1;33m([0m[0margs[0m[1;33m,[0m [0mkw[0m[1;33m,[0m [0msig[0m[1;33m)[0m[1;33m[0m[1;33m[0m[0m
[1;32m--> 232[1;33m             [1;32mreturn[0m [0mcaller[0m[1;33m([0m[0mfunc[0m[1;33m,[0m [1;33m*[0m[1;33m([0m[0mextras[0m [1;33m+[0m [0margs[0m[1;33m)[0m[1;33m,[0m [1;33m**[0m[0mkw[0m[1;33m)[0m[1;33m[0m[1;33m[0m[0m
[0m[0;32m    233[0m     [0mfun[0m[1;33m.[0m[0m__name__[0m [1;33m=[0m [0mfunc[0m[1;33m.[0m[0m__name__[0m[1;33m[0m[1;33m[0m[0m
[0;32m    234[0m     [0mfun[0m[1;33m.[0m[0m__doc__[0m [1;33m=[0m [0mfunc[0m[1;33m.[0m[0m__doc__[0m[1;33m[0m[1;33m[0m[0m

[1;32mC:\ProgramData\anaconda3\Lib\site-packages\IPython\core\magic.py[0m in [0;36m<lambda>[1;34m(f, *a, **k)[0m
[0;32m    185[0m     [1;31m# but it's overkill for just that one bit of state.[0m[1;33m[0m[1;33m[0m[0m
[0;32m    186[0m     [1;32mdef[0m [0mmagic_deco[0m[1;33m([0m[0marg[0m[1;33m)[0m[1;33m:[0m[1;33m[0m[1;33m[0m[0m
[1;32m--> 187[1;33m         [0mcall[0m [1;33m=[0m [1;32mlambda[0m [0mf[0m[1;33m,[0m [1;33m*[0m[0ma[0m[1;33m,[0m [1;33m**[0m[0mk[0m[1;33m:[0m [0mf[0m[1;33m([0m[1;33m*[0m[0ma[0m[1;33m,[0m [1;33m**[0m[0mk[0m[1;33m)[0m[1;33m[0m[1;33m[0m[0m
[0m[0;32m    188[0m [1;33m[0m[0m
[0;32m    189[0m         [1;32mif[0m [0mcallable[0m[1;33m([0m[0marg[0m[1;33m)[0m[1;33m:[0m[1;33m[0m[1;33m[0m[0m

[1;32mC:\ProgramData\anaconda3\Lib\site-packages\IPython\core\magics\execution.py[0m in [0;36mrun[1;34m(self, parameter_s, runner, file_finder)[0m
[0;32m    845[0m                     [1;32melse[0m[1;33m:[0m[1;33m[0m[1;33m[0m[0m
[0;32m    846[0m                         [1;31m# regular execution[0m[1;33m[0m[1;33m[0m[0m
[1;32m--> 847[1;33m                         [0mrun[0m[1;33m([0m[1;33m)[0m[1;33m[0m[1;33m[0m[0m
[0m[0;32m    848[0m [1;33m[0m[0m
[0;32m    849[0m             [1;32mif[0m [1;34m'i'[0m [1;32min[0m [0mopts[0m[1;33m:[0m[1;33m[0m[1;33m[0m[0m

[1;32mC:\ProgramData\anaconda3\Lib\site-packages\IPython\core\magics\execution.py[0m in [0;36mrun[1;34m()[0m
[0;32m    830[0m [1;33m[0m[0m
[0;32m    831[0m                         [1;32mdef[0m [0mrun[0m[1;33m([0m[1;33m)[0m[1;33m:[0m[1;33m[0m[1;33m[0m[0m
[1;32m--> 832[1;33m                             runner(filename, prog_ns, prog_ns,
[0m[0;32m    833[0m                                     exit_ignore=exit_ignore)
[0;32m    834[0m [1;33m[0m[0m

[1;32mC:\ProgramData\anaconda3\Lib\site-packages\IPython\core\interactiveshell.py[0m in [0;36msafe_execfile[1;34m(self, fname, exit_ignore, raise_exceptions, shell_futures, *where)[0m
[0;32m   2846[0m                         [1;32mraise[0m[1;33m[0m[1;33m[0m[0m
[0;32m   2847[0m                     [1;32mif[0m [1;32mnot[0m [0mexit_ignore[0m[1;33m:[0m[1;33m[0m[1;33m[0m[0m
[1;32m-> 2848[1;33m                         [0mself[0m[1;33m.[0m[0mshowtraceback[0m[1;33m([0m[0mexception_only[0m[1;33m=[0m[1;32mTrue[0m[1;33m)[0m[1;33m[0m[1;33m[0m[0m
[0m[0;32m   2849[0m             [1;32mexcept[0m[1;33m:[0m[1;33m[0m[1;33m[0m[0m
[0;32m   2850[0m                 [1;32mif[0m [0mraise_exceptions[0m[1;33m:[0m[1;33m[0m[1;33m[0m[0m

[1;32mC:\ProgramData\anaconda3\Lib\site-packages\IPython\core\interactiveshell.py[0m in [0;36mshowtraceback[1;34m(self, exc_tuple, filename, tb_offset, exception_only, running_compiled_code)[0m
[0;32m   2090[0m                     stb = ['An exception has occurred, use %tb to see '
[0;32m   2091[0m                            'the full traceback.\n']
[1;32m-> 2092[1;33m                     stb.extend(self.InteractiveTB.get_exception_only(etype,
[0m[0;32m   2093[0m                                                                      value))
[0;32m   2094[0m                 [1;32melse[0m[1;33m:[0m[1;33m[0m[1;33m[0m[0m

[1;32mC:\ProgramData\anaconda3\Lib\site-packages\IPython\core\ultratb.py[0m in [0;36mget_exception_only[1;34m(self, etype, value)[0m
[0;32m    752[0m         [0mvalue[0m [1;33m:[0m [0mexception[0m [0mvalue[0m[1;33m[0m[1;33m[0m[0m
[0;32m    753[0m         """
[1;32m--> 754[1;33m         [1;32mreturn[0m [0mListTB[0m[1;33m.[0m[0mstructured_traceback[0m[1;33m([0m[0mself[0m[1;33m,[0m [0metype[0m[1;33m,[0m [0mvalue[0m[1;33m)[0m[1;33m[0m[1;33m[0m[0m
[0m[0;32m    755[0m [1;33m[0m[0m
[0;32m    756[0m     [1;32mdef[0m [0mshow_exception_only[0m[1;33m([0m[0mself[0m[1;33m,[0m [0metype[0m[1;33m,[0m [0mevalue[0m[1;33m)[0m[1;33m:[0m[1;33m[0m[1;33m[0m[0m

[1;32mC:\ProgramData\anaconda3\Lib\site-packages\IPython\core\ultratb.py[0m in [0;36mstructured_traceback[1;34m(self, etype, evalue, etb, tb_offset, context)[0m
[0;32m    627[0m             [0mchained_exceptions_tb_offset[0m [1;33m=[0m [1;36m0[0m[1;33m[0m[1;33m[0m[0m
[0;32m    628[0m             out_list = (
[1;32m--> 629[1;33m                 self.structured_traceback(
[0m[0;32m    630[0m                     [0metype[0m[1;33m,[0m [0mevalue[0m[1;33m,[0m [1;33m([0m[0metb[0m[1;33m,[0m [0mchained_exc_ids[0m[1;33m)[0m[1;33m,[0m[1;33m[0m[1;33m[0m[0m
[0;32m    631[0m                     chained_exceptions_tb_offset, context)

[1;32mC:\ProgramData\anaconda3\Lib\site-packages\IPython\core\ultratb.py[0m in [0;36mstructured_traceback[1;34m(self, etype, value, tb, tb_offset, number_of_lines_of_context)[0m
[0;32m   1365[0m         [1;32melse[0m[1;33m:[0m[1;33m[0m[1;33m[0m[0m
[0;32m   1366[0m             [0mself[0m[1;33m.[0m[0mtb[0m [1;33m=[0m [0mtb[0m[1;33m[0m[1;33m[0m[0m
[1;32m-> 1367[1;33m         return FormattedTB.structured_traceback(
[0m[0;32m   1368[0m             self, etype, value, tb, tb_offset, number_of_lines_of_context)
[0;32m   1369[0m [1;33m[0m[0m

[1;32mC:\ProgramData\anaconda3\Lib\site-packages\IPython\core\ultratb.py[0m in [0;36mstructured_traceback[1;34m(self, etype, value, tb, tb_offset, number_of_lines_of_context)[0m
[0;32m   1265[0m         [1;32mif[0m [0mmode[0m [1;32min[0m [0mself[0m[1;33m.[0m[0mverbose_modes[0m[1;33m:[0m[1;33m[0m[1;33m[0m[0m
[0;32m   1266[0m             [1;31m# Verbose modes need a full traceback[0m[1;33m[0m[1;33m[0m[0m
[1;32m-> 1267[1;33m             return VerboseTB.structured_traceback(
[0m[0;32m   1268[0m                 [0mself[0m[1;33m,[0m [0metype[0m[1;33m,[0m [0mvalue[0m[1;33m,[0m [0mtb[0m[1;33m,[0m [0mtb_offset[0m[1;33m,[0m [0mnumber_of_lines_of_context[0m[1;33m[0m[1;33m[0m[0m
[0;32m   1269[0m             )

[1;32mC:\ProgramData\anaconda3\Lib\site-packages\IPython\core\ultratb.py[0m in [0;36mstructured_traceback[1;34m(self, etype, evalue, etb, tb_offset, number_of_lines_of_context)[0m
[0;32m   1122[0m         [1;34m"""Return a nice text document describing the traceback."""[0m[1;33m[0m[1;33m[0m[0m
[0;32m   1123[0m [1;33m[0m[0m
[1;32m-> 1124[1;33m         formatted_exception = self.format_exception_as_a_whole(etype, evalue, etb, number_of_lines_of_context,
[0m[0;32m   1125[0m                                                                tb_offset)
[0;32m   1126[0m [1;33m[0m[0m

[1;32mC:\ProgramData\anaconda3\Lib\site-packages\IPython\core\ultratb.py[0m in [0;36mformat_exception_as_a_whole[1;34m(self, etype, evalue, etb, number_of_lines_of_context, tb_offset)[0m
[0;32m   1080[0m [1;33m[0m[0m
[0;32m   1081[0m [1;33m[0m[0m
[1;32m-> 1082[1;33m         [0mlast_unique[0m[1;33m,[0m [0mrecursion_repeat[0m [1;33m=[0m [0mfind_recursion[0m[1;33m([0m[0morig_etype[0m[1;33m,[0m [0mevalue[0m[1;33m,[0m [0mrecords[0m[1;33m)[0m[1;33m[0m[1;33m[0m[0m
[0m[0;32m   1083[0m [1;33m[0m[0m
[0;32m   1084[0m         [0mframes[0m [1;33m=[0m [0mself[0m[1;33m.[0m[0mformat_records[0m[1;33m([0m[0mrecords[0m[1;33m,[0m [0mlast_unique[0m[1;33m,[0m [0mrecursion_repeat[0m[1;33m)[0m[1;33m[0m[1;33m[0m[0m

[1;32mC:\ProgramData\anaconda3\Lib\site-packages\IPython\core\ultratb.py[0m in [0;36mfind_recursion[1;34m(etype, value, records)[0m
[0;32m    380[0m     [1;31m# first frame (from in to out) that looks different.[0m[1;33m[0m[1;33m[0m[0m
[0;32m    381[0m     [1;32mif[0m [1;32mnot[0m [0mis_recursion_error[0m[1;33m([0m[0metype[0m[1;33m,[0m [0mvalue[0m[1;33m,[0m [0mrecords[0m[1;33m)[0m[1;33m:[0m[1;33m[0m[1;33m[0m[0m
[1;32m--> 382[1;33m         [1;32mreturn[0m [0mlen[0m[1;33m([0m[0mrecords[0m[1;33m)[0m[1;33m,[0m [1;36m0[0m[1;33m[0m[1;33m[0m[0m
[0m[0;32m    383[0m [1;33m[0m[0m
[0;32m    384[0m     [1;31m# Select filename, lineno, func_name to track frames with[0m[1;33m[0m[1;33m[0m[0m

[1;31mTypeError[0m: object of type 'NoneType' has no len()
TypeError: object of type 'NoneType' has no len()

